<?xml version="1.0" ?>
<!-- =================================================================================== -->
<!-- |    This document was autogenerated by xacro from my_robotic_arm.urdf.xacro      | -->
<!-- |    EDITING THIS FILE BY HAND IS NOT RECOMMENDED                                 | -->
<!-- =================================================================================== -->
<robot name="my_robotic_arm">
  <material name="white">
    <color rgba="1 1 1 1"/>
  </material>
  <link name="base_link">
    <visual>
      <geometry>
        <cylinder length="0.05" radius="0.05"/>
      </geometry>
      <origin rpy="0 0 0" xyz="0 0 0.025"/>
      <material name="white"/>
    </visual>
    <collision>
      <geometry>
        <cylinder length="0.05" radius="0.05"/>
      </geometry>
      <origin rpy="0 0 0" xyz="0 0 0.025"/>
    </collision>
  </link>
  <link name="first_link">
    <visual>
      <geometry>
        <cylinder length="0.2" radius="0.03"/>
      </geometry>
      <origin rpy="0 0 0" xyz="0 0 0.1"/>
      <material name="white"/>
    </visual>
    <collision>
      <geometry>
        <cylinder length="0.16" radius="0.019999999999999997"/>
      </geometry>
      <origin rpy="0 0 0" xyz="0 0 0.115"/>
    </collision>
    <inertial>
      <origin rpy="0 0 0" xyz="0 0 0"/>
      <mass value="0.8"/>
      <inertia ixx="0.002846666666666667" ixy="0" ixz="0" iyy="0.002846666666666667" iyz="0" izz="0.00035999999999999997"/>
    </inertial>
  </link>
  <link name="second_link">
    <visual>
      <geometry>
        <cylinder length="0.2" radius="0.03"/>
      </geometry>
      <origin rpy="0 0 0" xyz="0 0 0.1"/>
      <material name="white"/>
    </visual>
    <collision>
      <geometry>
        <cylinder length="0.16" radius="0.019999999999999997"/>
      </geometry>
      <origin rpy="0 0 0" xyz="0 0 0.115"/>
    </collision>
    <inertial>
      <origin rpy="0 0 0" xyz="0 0 0"/>
      <mass value="0.8"/>
      <inertia ixx="0.002846666666666667" ixy="0" ixz="0" iyy="0.002846666666666667" iyz="0" izz="0.00035999999999999997"/>
    </inertial>
  </link>
  <link name="third_link">
    <visual>
      <geometry>
        <cylinder length="0.2" radius="0.03"/>
      </geometry>
      <origin rpy="0 0 0" xyz="0 0 0.1"/>
      <material name="white"/>
    </visual>
    <collision>
      <geometry>
        <cylinder length="0.16" radius="0.019999999999999997"/>
      </geometry>
      <origin rpy="0 0 0" xyz="0 0 0.115"/>
    </collision>
    <inertial>
      <origin rpy="0 0 0" xyz="0 0 0"/>
      <mass value="0.8"/>
      <inertia ixx="0.002846666666666667" ixy="0" ixz="0" iyy="0.002846666666666667" iyz="0" izz="0.00035999999999999997"/>
    </inertial>
  </link>
  <link name="tcp_link"/>
  <joint name="base_first_joint" type="revolute">
    <parent link="base_link"/>
    <child link="first_link"/>
    <origin rpy="0 0 0" xyz="0 0 0.05"/>
    <axis xyz="0 0 1"/>
    <limit effort="20" lower="-3.14" upper="3.14" velocity="3.14"/>
  </joint>
  <joint name="first_second_joint" type="revolute">
    <parent link="first_link"/>
    <child link="second_link"/>
    <origin rpy="0 0 0" xyz="0 0 0.2"/>
    <axis xyz="1 0 0"/>
    <limit effort="20" lower="-3.14" upper="3.14" velocity="3.14"/>
  </joint>
  <joint name="second_third_joint" type="revolute">
    <parent link="second_link"/>
    <child link="third_link"/>
    <origin rpy="0 0 0" xyz="0 0 0.2"/>
    <axis xyz="1 0 0"/>
    <limit effort="20" lower="-3.14" upper="3.14" velocity="3.14"/>
  </joint>
  <joint name="tcp" type="fixed">
    <parent link="third_link"/>
    <child link="tcp_link"/>
    <origin rpy="0 0 0" xyz="0 0 0.2"/>
  </joint>
</robot>
